import axios from "axios"

import monAPI from "@/lib/monAPI"

import {
  CreateReminderType,
  ReminderType,
  UpdateReminderType
} from "@/schemas/reminderSchema"

export const getRemindersByUserId = async (
  userId: string | undefined
): Promise<ReminderType[]> => {
  try {
    const response = await monAPI.get(`/reminders/user/${userId}`)

    if (!response || !response.data) {
      throw {
        isCustomError: true,
        message:
          "Không nhận được phản hồi từ máy chủ. Có thể máy chủ đang gặp sự cố hoặc kết nối mạng của bạn bị gián đoạn"
      }
    }

    const { success, message, data } = response.data

    if (success) {
      return data as ReminderType[]
    } else {
      throw {
        isCustomError: true,
        message: message || "Không thể lấy danh sách nhắc nhở"
      }
    }
  } catch (error: any) {
    if (axios.isAxiosError(error)) {
      console.log("Lỗi từ server:", error.response?.data || error.message)
      throw error
    } else {
      console.log("Lỗi không phải Axios:", error)
      throw {
        isCustomError: true,
        message: "Đã xảy ra lỗi không mong muốn"
      }
    }
  }
}

export const getReminderById = async (
  reminderId: string | undefined
): Promise<ReminderType> => {
  try {
    const response = await monAPI.get(`/reminders/${reminderId}`)

    if (!response || !response.data) {
      throw {
        isCustomError: true,
        message:
          "Không nhận được phản hồi từ máy chủ. Có thể máy chủ đang gặp sự cố hoặc kết nối mạng của bạn bị gián đoạn"
      }
    }

    const { success, message, data } = response.data

    if (success) {
      return data as ReminderType
    } else {
      throw {
        isCustomError: true,
        message: message || "Không thể lấy thông tin chi tiết nhắc nhở"
      }
    }
  } catch (error: any) {
    if (axios.isAxiosError(error)) {
      console.log("Lỗi từ server:", error.response?.data || error.message)
      throw error
    } else {
      console.log("Lỗi không phải Axios:", error)
      throw {
        isCustomError: true,
        message: "Đã xảy ra lỗi không mong muốn"
      }
    }
  }
}

export const createReminder = async (
  newReminderData: CreateReminderType,
  showModal: (message: string) => void
): Promise<string> => {
  try {
    const response = await monAPI.post(`/reminders`, newReminderData)

    if (!response || !response.data) {
      throw {
        isCustomError: true,
        message:
          "Không nhận được phản hồi từ máy chủ. Có thể máy chủ đang gặp sự cố hoặc kết nối mạng của bạn bị gián đoạn"
      }
    }

    const { success, message } = response.data

    if (!success) {
      throw {
        isCustomError: true,
        message: message || "Không thể tạo nhắc nhở mới"
      }
    }

    showModal(message || "Tạo nhắc nhở thành công")

    console.log(message)
    return message
  } catch (error: any) {
    if (axios.isAxiosError(error)) {
      showModal("Đã xảy ra lỗi khi tạo nhắc nhở")

      console.log("Lỗi từ server:", error.response?.data || error.message)
      throw error
    } else {
      showModal("Đã xảy ra lỗi không mong muốn")

      console.log("Lỗi không phải Axios:", error)
      throw {
        isCustomError: true,
        message: "Đã xảy ra lỗi không mong muốn"
      }
    }
  }
}

export const updateReminder = async (
  reminderId: string,
  reminderData: UpdateReminderType,
  showModal: (message: string) => void
): Promise<string> => {
  try {
    const response = await monAPI.put(`/reminders/${reminderId}`, reminderData)

    if (!response || !response.data) {
      throw {
        isCustomError: true,
        message:
          "Không nhận được phản hồi từ máy chủ. Có thể máy chủ đang gặp sự cố hoặc kết nối mạng của bạn bị gián đoạn"
      }
    }

    const { success, message } = response.data

    if (!success) {
      throw {
        isCustomError: true,
        message: message || "Không thể cập nhật nhắc nhở"
      }
    }

    showModal(message || "Cập nhật nhắc nhở thành công")

    console.log(message)
    return message
  } catch (error: any) {
    if (axios.isAxiosError(error)) {
      showModal("Đã xảy ra lỗi khi cập nhật nhắc nhở")

      console.log("Lỗi từ server:", error.response?.data || error.message)
      throw error
    } else {
      showModal("Đã xảy ra lỗi không mong muốn")

      console.log("Lỗi không phải Axios:", error)
      throw {
        isCustomError: true,
        message: "Đã xảy ra lỗi không mong muốn"
      }
    }
  }
}

export const updateReminderStatus = async (
  reminderId: string
): Promise<string> => {
  try {
    const response = await monAPI.patch(`/reminders/${reminderId}/status`)

    if (!response || !response.data) {
      throw {
        isCustomError: true,
        message:
          "Không nhận được phản hồi từ máy chủ. Có thể máy chủ đang gặp sự cố hoặc kết nối mạng của bạn bị gián đoạn"
      }
    }

    const { success, message } = response.data

    if (!success) {
      throw {
        isCustomError: true,
        message: message || "Không thể cập nhật trạng thái"
      }
    }

    console.log(message)
    return message
  } catch (error: any) {
    if (axios.isAxiosError(error)) {
      console.log("Lỗi từ server:", error.response?.data || error.message)
      throw error
    } else {
      console.log("Lỗi không phải Axios:", error)
      throw {
        isCustomError: true,
        message: "Đã xảy ra lỗi không mong muốn"
      }
    }
  }
}

export const deleteReminder = async (reminderId: string): Promise<string> => {
  try {
    const response = await monAPI.delete(`/reminders/${reminderId}`)

    if (!response || !response.data) {
      throw {
        isCustomError: true,
        message:
          "Không nhận được phản hồi từ máy chủ. Có thể máy chủ đang gặp sự cố hoặc kết nối mạng của bạn bị gián đoạn"
      }
    }

    const { success, message } = response.data

    if (!success) {
      throw {
        isCustomError: true,
        message: message || "Không thể xóa nhắc nhở"
      }
    }

    console.log(message)
    return message
  } catch (error: any) {
    if (axios.isAxiosError(error)) {
      console.log("Lỗi từ server:", error.response?.data || error.message)
      throw error
    } else {
      console.log("Lỗi không phải Axios:", error)
      throw {
        isCustomError: true,
        message: "Đã xảy ra lỗi không mong muốn"
      }
    }
  }
}
